C:\Users\Novinpro.ir\Desktop\my telegram bot\bot.py:415: PTBUserWarning: If 'per_message=False', 'CallbackQueryHandler' will not be tracked for every message. Read this FAQ entry to learn more about the per_* settings: https://github.com/python-telegram-bot/python-telegram-bot/wiki/Frequently-Asked-Questions#what-do-the-per_-settings-in-conversationhandler-do.
  conv_handler = ConversationHandler(
^CC:\Users\Novinpro.ir\Desktop\my telegram bot\bot.py:416: PTBUserWarning: If 'per_message=False', 'CallbackQueryHandler' will not be tracked for every message. Read this FAQ entry to learn more about the per_* settings: https://github.com/python-telegram-bot/python-telegram-bot/wiki/Frequently-Asked-Questions#what-do-the-per_-settings-in-conversationhandler-do.
  conv_handler = ConversationHandler(
^CC:\Users\Novinpro.ir\Desktop\my telegram bot\bot.py:417: PTBUserWarning: If 'per_message=False', 'CallbackQueryHandler' will not be tracked for every message. Read this FAQ entry to learn more about the per_* settings: https://github.com/python-telegram-bot/python-telegram-bot/wiki/Frequently-Asked-Questions#what-do-the-per_-settings-in-conversationhandler-do.
  conv_handler = ConversationHandler(
^CC:\Users\Novinpro.ir\Desktop\my telegram bot\bot.py:416: PTBUserWarning: If 'per_message=False', 'CallbackQueryHandler' will not be tracked for every message. Read this FAQ entry to learn more about the per_* settings: https://github.com/python-telegram-bot/python-telegram-bot/wiki/Frequently-Asked-Questions#what-do-the-per_-settings-in-conversationhandler-do.
  conv_handler = ConversationHandler(
No error handlers are registered, logging exception.
Traceback (most recent call last):
  File "C:\Users\Novinpro.ir\AppData\Local\Programs\Python\Python311\Lib\site-packages\httpx\_transports\default.py", line 101, in map_httpcore_exceptions
    yield
  File "C:\Users\Novinpro.ir\AppData\Local\Programs\Python\Python311\Lib\site-packages\httpx\_transports\default.py", line 394, in handle_async_request
    resp = await self._pool.handle_async_request(req)
           ^^^^^^^^^^^^^^^^^^^^^^^^^^^^^^^^^^^^^^^^^^
  File "C:\Users\Novinpro.ir\AppData\Local\Programs\Python\Python311\Lib\site-packages\httpcore\_async\connection_pool.py", line 256, in handle_async_request
    raise exc from None
  File "C:\Users\Novinpro.ir\AppData\Local\Programs\Python\Python311\Lib\site-packages\httpcore\_async\connection_pool.py", line 236, in handle_async_request
    response = await connection.handle_async_request(
               ^^^^^^^^^^^^^^^^^^^^^^^^^^^^^^^^^^^^^^
  File "C:\Users\Novinpro.ir\AppData\Local\Programs\Python\Python311\Lib\site-packages\httpcore\_async\http_proxy.py", line 316, in handle_async_request
    stream = await stream.start_tls(**kwargs)
             ^^^^^^^^^^^^^^^^^^^^^^^^^^^^^^^^
  File "C:\Users\Novinpro.ir\AppData\Local\Programs\Python\Python311\Lib\site-packages\httpcore\_async\http11.py", line 376, in start_tls
    return await self._stream.start_tls(ssl_context, server_hostname, timeout)
           ^^^^^^^^^^^^^^^^^^^^^^^^^^^^^^^^^^^^^^^^^^^^^^^^^^^^^^^^^^^^^^^^^^^
  File "C:\Users\Novinpro.ir\AppData\Local\Programs\Python\Python311\Lib\site-packages\httpcore\_backends\anyio.py", line 67, in start_tls
    with map_exceptions(exc_map):
  File "C:\Users\Novinpro.ir\AppData\Local\Programs\Python\Python311\Lib\contextlib.py", line 155, in __exit__
    self.gen.throw(typ, value, traceback)
  File "C:\Users\Novinpro.ir\AppData\Local\Programs\Python\Python311\Lib\site-packages\httpcore\_exceptions.py", line 14, in map_exceptions
    raise to_exc(exc) from exc
httpcore.ConnectTimeout

The above exception was the direct cause of the following exception:

Traceback (most recent call last):
  File "C:\Users\Novinpro.ir\AppData\Local\Programs\Python\Python311\Lib\site-packages\telegram\request\_httpxrequest.py", line 273, in do_request
    res = await self._client.request(
          ^^^^^^^^^^^^^^^^^^^^^^^^^^^
  File "C:\Users\Novinpro.ir\AppData\Local\Programs\Python\Python311\Lib\site-packages\httpx\_client.py", line 1540, in request
    return await self.send(request, auth=auth, follow_redirects=follow_redirects)
           ^^^^^^^^^^^^^^^^^^^^^^^^^^^^^^^^^^^^^^^^^^^^^^^^^^^^^^^^^^^^^^^^^^^^^^
  File "C:\Users\Novinpro.ir\AppData\Local\Programs\Python\Python311\Lib\site-packages\httpx\_client.py", line 1629, in send
    response = await self._send_handling_auth(
               ^^^^^^^^^^^^^^^^^^^^^^^^^^^^^^^
  File "C:\Users\Novinpro.ir\AppData\Local\Programs\Python\Python311\Lib\site-packages\httpx\_client.py", line 1657, in _send_handling_auth
    response = await self._send_handling_redirects(
               ^^^^^^^^^^^^^^^^^^^^^^^^^^^^^^^^^^^^
  File "C:\Users\Novinpro.ir\AppData\Local\Programs\Python\Python311\Lib\site-packages\httpx\_client.py", line 1694, in _send_handling_redirects
    response = await self._send_single_request(request)
               ^^^^^^^^^^^^^^^^^^^^^^^^^^^^^^^^^^^^^^^^
  File "C:\Users\Novinpro.ir\AppData\Local\Programs\Python\Python311\Lib\site-packages\httpx\_client.py", line 1730, in _send_single_request
    response = await transport.handle_async_request(request)
               ^^^^^^^^^^^^^^^^^^^^^^^^^^^^^^^^^^^^^^^^^^^^^
  File "C:\Users\Novinpro.ir\AppData\Local\Programs\Python\Python311\Lib\site-packages\httpx\_transports\default.py", line 393, in handle_async_request
    with map_httpcore_exceptions():
  File "C:\Users\Novinpro.ir\AppData\Local\Programs\Python\Python311\Lib\contextlib.py", line 155, in __exit__
    self.gen.throw(typ, value, traceback)
  File "C:\Users\Novinpro.ir\AppData\Local\Programs\Python\Python311\Lib\site-packages\httpx\_transports\default.py", line 118, in map_httpcore_exceptions
    raise mapped_exc(message) from exc
httpx.ConnectTimeout

The above exception was the direct cause of the following exception:

Traceback (most recent call last):
  File "C:\Users\Novinpro.ir\AppData\Local\Programs\Python\Python311\Lib\site-packages\telegram\ext\_application.py", line 1309, in process_update
    await coroutine
  File "C:\Users\Novinpro.ir\AppData\Local\Programs\Python\Python311\Lib\site-packages\telegram\ext\_handlers\conversationhandler.py", line 842, in handle_update
    new_state: object = await handler.handle_update(
                        ^^^^^^^^^^^^^^^^^^^^^^^^^^^^
  File "C:\Users\Novinpro.ir\AppData\Local\Programs\Python\Python311\Lib\site-packages\telegram\ext\_handlers\basehandler.py", line 158, in handle_update
    return await self.callback(update, context)
           ^^^^^^^^^^^^^^^^^^^^^^^^^^^^^^^^^^^^
  File "C:\Users\Novinpro.ir\Desktop\my telegram bot\bot.py", line 167, in ask_bet
    await update.message.reply_text(text, reply_markup=keyboard)
  File "C:\Users\Novinpro.ir\AppData\Local\Programs\Python\Python311\Lib\site-packages\telegram\_message.py", line 1851, in reply_text
    return await self.get_bot().send_message(
           ^^^^^^^^^^^^^^^^^^^^^^^^^^^^^^^^^^
  File "C:\Users\Novinpro.ir\AppData\Local\Programs\Python\Python311\Lib\site-packages\telegram\ext\_extbot.py", line 2988, in send_message
    return await super().send_message(
           ^^^^^^^^^^^^^^^^^^^^^^^^^^^
  File "C:\Users\Novinpro.ir\AppData\Local\Programs\Python\Python311\Lib\site-packages\telegram\_bot.py", line 1099, in send_message
    return await self._send_message(
           ^^^^^^^^^^^^^^^^^^^^^^^^^
  File "C:\Users\Novinpro.ir\AppData\Local\Programs\Python\Python311\Lib\site-packages\telegram\ext\_extbot.py", line 629, in _send_message
    result = await super()._send_message(
             ^^^^^^^^^^^^^^^^^^^^^^^^^^^^
  File "C:\Users\Novinpro.ir\AppData\Local\Programs\Python\Python311\Lib\site-packages\telegram\_bot.py", line 809, in _send_message
    result = await self._post(
             ^^^^^^^^^^^^^^^^^
  File "C:\Users\Novinpro.ir\AppData\Local\Programs\Python\Python311\Lib\site-packages\telegram\_bot.py", line 697, in _post
    return await self._do_post(
           ^^^^^^^^^^^^^^^^^^^^
  File "C:\Users\Novinpro.ir\AppData\Local\Programs\Python\Python311\Lib\site-packages\telegram\ext\_extbot.py", line 369, in _do_post
    return await super()._do_post(
           ^^^^^^^^^^^^^^^^^^^^^^^
  File "C:\Users\Novinpro.ir\AppData\Local\Programs\Python\Python311\Lib\site-packages\telegram\_bot.py", line 726, in _do_post
    result = await request.post(
             ^^^^^^^^^^^^^^^^^^^
  File "C:\Users\Novinpro.ir\AppData\Local\Programs\Python\Python311\Lib\site-packages\telegram\request\_baserequest.py", line 197, in post
    result = await self._request_wrapper(
             ^^^^^^^^^^^^^^^^^^^^^^^^^^^^
  File "C:\Users\Novinpro.ir\AppData\Local\Programs\Python\Python311\Lib\site-packages\telegram\request\_baserequest.py", line 304, in _request_wrapper
    code, payload = await self.do_request(
                    ^^^^^^^^^^^^^^^^^^^^^^
  File "C:\Users\Novinpro.ir\AppData\Local\Programs\Python\Python311\Lib\site-packages\telegram\request\_httpxrequest.py", line 290, in do_request
    raise TimedOut from err
telegram.error.TimedOut: Timed out
No error handlers are registered, logging exception.
Traceback (most recent call last):
  File "C:\Users\Novinpro.ir\AppData\Local\Programs\Python\Python311\Lib\site-packages\httpx\_transports\default.py", line 101, in map_httpcore_exceptions
    yield
  File "C:\Users\Novinpro.ir\AppData\Local\Programs\Python\Python311\Lib\site-packages\httpx\_transports\default.py", line 394, in handle_async_request
    resp = await self._pool.handle_async_request(req)
           ^^^^^^^^^^^^^^^^^^^^^^^^^^^^^^^^^^^^^^^^^^
  File "C:\Users\Novinpro.ir\AppData\Local\Programs\Python\Python311\Lib\site-packages\httpcore\_async\connection_pool.py", line 256, in handle_async_request
    raise exc from None
  File "C:\Users\Novinpro.ir\AppData\Local\Programs\Python\Python311\Lib\site-packages\httpcore\_async\connection_pool.py", line 236, in handle_async_request
    response = await connection.handle_async_request(
               ^^^^^^^^^^^^^^^^^^^^^^^^^^^^^^^^^^^^^^
  File "C:\Users\Novinpro.ir\AppData\Local\Programs\Python\Python311\Lib\site-packages\httpcore\_async\http_proxy.py", line 316, in handle_async_request
    stream = await stream.start_tls(**kwargs)
             ^^^^^^^^^^^^^^^^^^^^^^^^^^^^^^^^
  File "C:\Users\Novinpro.ir\AppData\Local\Programs\Python\Python311\Lib\site-packages\httpcore\_async\http11.py", line 376, in start_tls
    return await self._stream.start_tls(ssl_context, server_hostname, timeout)
           ^^^^^^^^^^^^^^^^^^^^^^^^^^^^^^^^^^^^^^^^^^^^^^^^^^^^^^^^^^^^^^^^^^^
  File "C:\Users\Novinpro.ir\AppData\Local\Programs\Python\Python311\Lib\site-packages\httpcore\_backends\anyio.py", line 67, in start_tls
    with map_exceptions(exc_map):
  File "C:\Users\Novinpro.ir\AppData\Local\Programs\Python\Python311\Lib\contextlib.py", line 155, in __exit__
    self.gen.throw(typ, value, traceback)
  File "C:\Users\Novinpro.ir\AppData\Local\Programs\Python\Python311\Lib\site-packages\httpcore\_exceptions.py", line 14, in map_exceptions
    raise to_exc(exc) from exc
httpcore.ConnectTimeout

The above exception was the direct cause of the following exception:

Traceback (most recent call last):
  File "C:\Users\Novinpro.ir\AppData\Local\Programs\Python\Python311\Lib\site-packages\telegram\request\_httpxrequest.py", line 273, in do_request
    res = await self._client.request(
          ^^^^^^^^^^^^^^^^^^^^^^^^^^^
  File "C:\Users\Novinpro.ir\AppData\Local\Programs\Python\Python311\Lib\site-packages\httpx\_client.py", line 1540, in request
    return await self.send(request, auth=auth, follow_redirects=follow_redirects)
           ^^^^^^^^^^^^^^^^^^^^^^^^^^^^^^^^^^^^^^^^^^^^^^^^^^^^^^^^^^^^^^^^^^^^^^
  File "C:\Users\Novinpro.ir\AppData\Local\Programs\Python\Python311\Lib\site-packages\httpx\_client.py", line 1629, in send
    response = await self._send_handling_auth(
               ^^^^^^^^^^^^^^^^^^^^^^^^^^^^^^^
  File "C:\Users\Novinpro.ir\AppData\Local\Programs\Python\Python311\Lib\site-packages\httpx\_client.py", line 1657, in _send_handling_auth
    response = await self._send_handling_redirects(
               ^^^^^^^^^^^^^^^^^^^^^^^^^^^^^^^^^^^^
  File "C:\Users\Novinpro.ir\AppData\Local\Programs\Python\Python311\Lib\site-packages\httpx\_client.py", line 1694, in _send_handling_redirects
    response = await self._send_single_request(request)
               ^^^^^^^^^^^^^^^^^^^^^^^^^^^^^^^^^^^^^^^^
  File "C:\Users\Novinpro.ir\AppData\Local\Programs\Python\Python311\Lib\site-packages\httpx\_client.py", line 1730, in _send_single_request
    response = await transport.handle_async_request(request)
               ^^^^^^^^^^^^^^^^^^^^^^^^^^^^^^^^^^^^^^^^^^^^^
  File "C:\Users\Novinpro.ir\AppData\Local\Programs\Python\Python311\Lib\site-packages\httpx\_transports\default.py", line 393, in handle_async_request
    with map_httpcore_exceptions():
  File "C:\Users\Novinpro.ir\AppData\Local\Programs\Python\Python311\Lib\contextlib.py", line 155, in __exit__
    self.gen.throw(typ, value, traceback)
  File "C:\Users\Novinpro.ir\AppData\Local\Programs\Python\Python311\Lib\site-packages\httpx\_transports\default.py", line 118, in map_httpcore_exceptions
    raise mapped_exc(message) from exc
httpx.ConnectTimeout

The above exception was the direct cause of the following exception:

Traceback (most recent call last):
  File "C:\Users\Novinpro.ir\AppData\Local\Programs\Python\Python311\Lib\site-packages\telegram\ext\_application.py", line 1309, in process_update
    await coroutine
  File "C:\Users\Novinpro.ir\AppData\Local\Programs\Python\Python311\Lib\site-packages\telegram\ext\_handlers\conversationhandler.py", line 842, in handle_update
    new_state: object = await handler.handle_update(
                        ^^^^^^^^^^^^^^^^^^^^^^^^^^^^
  File "C:\Users\Novinpro.ir\AppData\Local\Programs\Python\Python311\Lib\site-packages\telegram\ext\_handlers\basehandler.py", line 158, in handle_update
    return await self.callback(update, context)
           ^^^^^^^^^^^^^^^^^^^^^^^^^^^^^^^^^^^^
  File "C:\Users\Novinpro.ir\Desktop\my telegram bot\bot.py", line 344, in withdraw_name
    return await deposit_withdraw_back(update, context)
           ^^^^^^^^^^^^^^^^^^^^^^^^^^^^^^^^^^^^^^^^^^^^
  File "C:\Users\Novinpro.ir\Desktop\my telegram bot\bot.py", line 379, in deposit_withdraw_back
    await update.message.reply_text("\u0628\u0647 \u0645\u0646\u0648\u06cc \u0627\u0635\u0644\u06cc \u0628\u0631\u06af\u0634\u062a\u06cc\u062f.", reply_markup=keyboard)
  File "C:\Users\Novinpro.ir\AppData\Local\Programs\Python\Python311\Lib\site-packages\telegram\_message.py", line 1851, in reply_text
    return await self.get_bot().send_message(
           ^^^^^^^^^^^^^^^^^^^^^^^^^^^^^^^^^^
  File "C:\Users\Novinpro.ir\AppData\Local\Programs\Python\Python311\Lib\site-packages\telegram\ext\_extbot.py", line 2988, in send_message
    return await super().send_message(
           ^^^^^^^^^^^^^^^^^^^^^^^^^^^
  File "C:\Users\Novinpro.ir\AppData\Local\Programs\Python\Python311\Lib\site-packages\telegram\_bot.py", line 1099, in send_message
    return await self._send_message(
           ^^^^^^^^^^^^^^^^^^^^^^^^^
  File "C:\Users\Novinpro.ir\AppData\Local\Programs\Python\Python311\Lib\site-packages\telegram\ext\_extbot.py", line 629, in _send_message
    result = await super()._send_message(
             ^^^^^^^^^^^^^^^^^^^^^^^^^^^^
  File "C:\Users\Novinpro.ir\AppData\Local\Programs\Python\Python311\Lib\site-packages\telegram\_bot.py", line 809, in _send_message
    result = await self._post(
             ^^^^^^^^^^^^^^^^^
  File "C:\Users\Novinpro.ir\AppData\Local\Programs\Python\Python311\Lib\site-packages\telegram\_bot.py", line 697, in _post
    return await self._do_post(
           ^^^^^^^^^^^^^^^^^^^^
  File "C:\Users\Novinpro.ir\AppData\Local\Programs\Python\Python311\Lib\site-packages\telegram\ext\_extbot.py", line 369, in _do_post
    return await super()._do_post(
           ^^^^^^^^^^^^^^^^^^^^^^^
  File "C:\Users\Novinpro.ir\AppData\Local\Programs\Python\Python311\Lib\site-packages\telegram\_bot.py", line 726, in _do_post
    result = await request.post(
             ^^^^^^^^^^^^^^^^^^^
  File "C:\Users\Novinpro.ir\AppData\Local\Programs\Python\Python311\Lib\site-packages\telegram\request\_baserequest.py", line 197, in post
    result = await self._request_wrapper(
             ^^^^^^^^^^^^^^^^^^^^^^^^^^^^
  File "C:\Users\Novinpro.ir\AppData\Local\Programs\Python\Python311\Lib\site-packages\telegram\request\_baserequest.py", line 304, in _request_wrapper
    code, payload = await self.do_request(
                    ^^^^^^^^^^^^^^^^^^^^^^
  File "C:\Users\Novinpro.ir\AppData\Local\Programs\Python\Python311\Lib\site-packages\telegram\request\_httpxrequest.py", line 290, in do_request
    raise TimedOut from err
telegram.error.TimedOut: Timed out
No error handlers are registered, logging exception.
Traceback (most recent call last):
  File "C:\Users\Novinpro.ir\AppData\Local\Programs\Python\Python311\Lib\site-packages\httpx\_transports\default.py", line 101, in map_httpcore_exceptions
    yield
  File "C:\Users\Novinpro.ir\AppData\Local\Programs\Python\Python311\Lib\site-packages\httpx\_transports\default.py", line 394, in handle_async_request
    resp = await self._pool.handle_async_request(req)
           ^^^^^^^^^^^^^^^^^^^^^^^^^^^^^^^^^^^^^^^^^^
  File "C:\Users\Novinpro.ir\AppData\Local\Programs\Python\Python311\Lib\site-packages\httpcore\_async\connection_pool.py", line 256, in handle_async_request
    raise exc from None
  File "C:\Users\Novinpro.ir\AppData\Local\Programs\Python\Python311\Lib\site-packages\httpcore\_async\connection_pool.py", line 236, in handle_async_request
    response = await connection.handle_async_request(
               ^^^^^^^^^^^^^^^^^^^^^^^^^^^^^^^^^^^^^^
  File "C:\Users\Novinpro.ir\AppData\Local\Programs\Python\Python311\Lib\site-packages\httpcore\_async\http_proxy.py", line 316, in handle_async_request
    stream = await stream.start_tls(**kwargs)
             ^^^^^^^^^^^^^^^^^^^^^^^^^^^^^^^^
  File "C:\Users\Novinpro.ir\AppData\Local\Programs\Python\Python311\Lib\site-packages\httpcore\_async\http11.py", line 376, in start_tls
    return await self._stream.start_tls(ssl_context, server_hostname, timeout)
           ^^^^^^^^^^^^^^^^^^^^^^^^^^^^^^^^^^^^^^^^^^^^^^^^^^^^^^^^^^^^^^^^^^^
  File "C:\Users\Novinpro.ir\AppData\Local\Programs\Python\Python311\Lib\site-packages\httpcore\_backends\anyio.py", line 67, in start_tls
    with map_exceptions(exc_map):
  File "C:\Users\Novinpro.ir\AppData\Local\Programs\Python\Python311\Lib\contextlib.py", line 155, in __exit__
    self.gen.throw(typ, value, traceback)
  File "C:\Users\Novinpro.ir\AppData\Local\Programs\Python\Python311\Lib\site-packages\httpcore\_exceptions.py", line 14, in map_exceptions
    raise to_exc(exc) from exc
httpcore.ConnectError

The above exception was the direct cause of the following exception:

Traceback (most recent call last):
  File "C:\Users\Novinpro.ir\AppData\Local\Programs\Python\Python311\Lib\site-packages\telegram\request\_httpxrequest.py", line 273, in do_request
    res = await self._client.request(
          ^^^^^^^^^^^^^^^^^^^^^^^^^^^
  File "C:\Users\Novinpro.ir\AppData\Local\Programs\Python\Python311\Lib\site-packages\httpx\_client.py", line 1540, in request
    return await self.send(request, auth=auth, follow_redirects=follow_redirects)
           ^^^^^^^^^^^^^^^^^^^^^^^^^^^^^^^^^^^^^^^^^^^^^^^^^^^^^^^^^^^^^^^^^^^^^^
  File "C:\Users\Novinpro.ir\AppData\Local\Programs\Python\Python311\Lib\site-packages\httpx\_client.py", line 1629, in send
    response = await self._send_handling_auth(
               ^^^^^^^^^^^^^^^^^^^^^^^^^^^^^^^
  File "C:\Users\Novinpro.ir\AppData\Local\Programs\Python\Python311\Lib\site-packages\httpx\_client.py", line 1657, in _send_handling_auth
    response = await self._send_handling_redirects(
               ^^^^^^^^^^^^^^^^^^^^^^^^^^^^^^^^^^^^
  File "C:\Users\Novinpro.ir\AppData\Local\Programs\Python\Python311\Lib\site-packages\httpx\_client.py", line 1694, in _send_handling_redirects
    response = await self._send_single_request(request)
               ^^^^^^^^^^^^^^^^^^^^^^^^^^^^^^^^^^^^^^^^
  File "C:\Users\Novinpro.ir\AppData\Local\Programs\Python\Python311\Lib\site-packages\httpx\_client.py", line 1730, in _send_single_request
    response = await transport.handle_async_request(request)
               ^^^^^^^^^^^^^^^^^^^^^^^^^^^^^^^^^^^^^^^^^^^^^
  File "C:\Users\Novinpro.ir\AppData\Local\Programs\Python\Python311\Lib\site-packages\httpx\_transports\default.py", line 393, in handle_async_request
    with map_httpcore_exceptions():
  File "C:\Users\Novinpro.ir\AppData\Local\Programs\Python\Python311\Lib\contextlib.py", line 155, in __exit__
    self.gen.throw(typ, value, traceback)
  File "C:\Users\Novinpro.ir\AppData\Local\Programs\Python\Python311\Lib\site-packages\httpx\_transports\default.py", line 118, in map_httpcore_exceptions
    raise mapped_exc(message) from exc
httpx.ConnectError

The above exception was the direct cause of the following exception:

Traceback (most recent call last):
  File "C:\Users\Novinpro.ir\AppData\Local\Programs\Python\Python311\Lib\site-packages\telegram\ext\_application.py", line 1309, in process_update
    await coroutine
  File "C:\Users\Novinpro.ir\AppData\Local\Programs\Python\Python311\Lib\site-packages\telegram\ext\_handlers\conversationhandler.py", line 842, in handle_update
    new_state: object = await handler.handle_update(
                        ^^^^^^^^^^^^^^^^^^^^^^^^^^^^
  File "C:\Users\Novinpro.ir\AppData\Local\Programs\Python\Python311\Lib\site-packages\telegram\ext\_handlers\basehandler.py", line 158, in handle_update
    return await self.callback(update, context)
           ^^^^^^^^^^^^^^^^^^^^^^^^^^^^^^^^^^^^
  File "C:\Users\Novinpro.ir\Desktop\my telegram bot\bot.py", line 318, in deposit_withdraw_menu
    await update.message.reply_text("\u06cc\u06a9\u06cc \u0627\u0632 \u06af\u0632\u06cc\u0646\u0647\u200c\u0647\u0627 \u0631\u0627 \u0627\u0646\u062a\u062e\u0627\u0628 \u06a9\u0646\u06cc\u062f:", reply_markup=keyboard)
  File "C:\Users\Novinpro.ir\AppData\Local\Programs\Python\Python311\Lib\site-packages\telegram\_message.py", line 1851, in reply_text
    return await self.get_bot().send_message(
           ^^^^^^^^^^^^^^^^^^^^^^^^^^^^^^^^^^
  File "C:\Users\Novinpro.ir\AppData\Local\Programs\Python\Python311\Lib\site-packages\telegram\ext\_extbot.py", line 2988, in send_message
    return await super().send_message(
           ^^^^^^^^^^^^^^^^^^^^^^^^^^^
  File "C:\Users\Novinpro.ir\AppData\Local\Programs\Python\Python311\Lib\site-packages\telegram\_bot.py", line 1099, in send_message
    return await self._send_message(
           ^^^^^^^^^^^^^^^^^^^^^^^^^
  File "C:\Users\Novinpro.ir\AppData\Local\Programs\Python\Python311\Lib\site-packages\telegram\ext\_extbot.py", line 629, in _send_message
    result = await super()._send_message(
             ^^^^^^^^^^^^^^^^^^^^^^^^^^^^
  File "C:\Users\Novinpro.ir\AppData\Local\Programs\Python\Python311\Lib\site-packages\telegram\_bot.py", line 809, in _send_message
    result = await self._post(
             ^^^^^^^^^^^^^^^^^
  File "C:\Users\Novinpro.ir\AppData\Local\Programs\Python\Python311\Lib\site-packages\telegram\_bot.py", line 697, in _post
    return await self._do_post(
           ^^^^^^^^^^^^^^^^^^^^
  File "C:\Users\Novinpro.ir\AppData\Local\Programs\Python\Python311\Lib\site-packages\telegram\ext\_extbot.py", line 369, in _do_post
    return await super()._do_post(
           ^^^^^^^^^^^^^^^^^^^^^^^
  File "C:\Users\Novinpro.ir\AppData\Local\Programs\Python\Python311\Lib\site-packages\telegram\_bot.py", line 726, in _do_post
    result = await request.post(
             ^^^^^^^^^^^^^^^^^^^
  File "C:\Users\Novinpro.ir\AppData\Local\Programs\Python\Python311\Lib\site-packages\telegram\request\_baserequest.py", line 197, in post
    result = await self._request_wrapper(
             ^^^^^^^^^^^^^^^^^^^^^^^^^^^^
  File "C:\Users\Novinpro.ir\AppData\Local\Programs\Python\Python311\Lib\site-packages\telegram\request\_baserequest.py", line 304, in _request_wrapper
    code, payload = await self.do_request(
                    ^^^^^^^^^^^^^^^^^^^^^^
  File "C:\Users\Novinpro.ir\AppData\Local\Programs\Python\Python311\Lib\site-packages\telegram\request\_httpxrequest.py", line 297, in do_request
    raise NetworkError(f"httpx.{err.__class__.__name__}: {err}") from err
telegram.error.NetworkError: httpx.ConnectError: 
^CC:\Users\Novinpro.ir\Desktop\my telegram bot\bot.py:416: PTBUserWarning: If 'per_message=False', 'CallbackQueryHandler' will not be tracked for every message. Read this FAQ entry to learn more about the per_* settings: https://github.com/python-telegram-bot/python-telegram-bot/wiki/Frequently-Asked-Questions#what-do-the-per_-settings-in-conversationhandler-do.
  conv_handler = ConversationHandler(
^CC:\Users\Novinpro.ir\Desktop\my telegram bot\bot.py:429: PTBUserWarning: If 'per_message=False', 'CallbackQueryHandler' will not be tracked for every message. Read this FAQ entry to learn more about the per_* settings: https://github.com/python-telegram-bot/python-telegram-bot/wiki/Frequently-Asked-Questions#what-do-the-per_-settings-in-conversationhandler-do.
  conv_handler = ConversationHandler(
^CC:\Users\Novinpro.ir\Desktop\my telegram bot\bot.py:417: PTBUserWarning: If 'per_message=False', 'CallbackQueryHandler' will not be tracked for every message. Read this FAQ entry to learn more about the per_* settings: https://github.com/python-telegram-bot/python-telegram-bot/wiki/Frequently-Asked-Questions#what-do-the-per_-settings-in-conversationhandler-do.
  conv_handler = ConversationHandler(
^CC:\Users\Novinpro.ir\Desktop\my telegram bot\bot.py:417: PTBUserWarning: If 'per_message=False', 'CallbackQueryHandler' will not be tracked for every message. Read this FAQ entry to learn more about the per_* settings: https://github.com/python-telegram-bot/python-telegram-bot/wiki/Frequently-Asked-Questions#what-do-the-per_-settings-in-conversationhandler-do.
  conv_handler = ConversationHandler(
^C